Workbook

Sheet 福盛世家 (演算)
B4: 投保信息 | S4: 交费期间 | T4: 一次交清 | U4: 3年交 | V4: 5年交 | W4: 10年交 | Y4: 交费期间 | Z4: 男 | AA4: 女
B5: 该计划是一款保费现金价值快速超过保费，合同约定年复利2.0%保额增长的终身寿险，通过时间的积累，生存利益和身故保障双增长，并可灵活减保支取现价，满足财富增值、教育、养老、资产保全、财富传承规划等需求，助您从容安排财富，规划美好人生。 | S5: 男 | T5: 68 | U5: 68 | V5: 67 | W5: 65 | Y5: 一次交清 | Z5: 70 | AA5: 74
B6: 被保险人 | D6: 性别 | E6: 年龄 | F6: 交费期间 | H6: =IF(F7="一次交清","保费","年交保费") | J6: 基本保额 | S6: 女 | T6: 72 | U6: 72 | V6: 70 | W6: 65 | Y6: 3年交 | Z6: 69 | AA6: 73
B7: vip | D7: 女 | E7: 59 | F7: 3年交 | H7: 50000 | J7: =VLOOKUP(Q7,保额!D:E,2,0)*H7/1000 | O7: =IF(F7="一次交清",1,IF(F7="3年交",3,IF(F7="5年交",5,10))) | Q7: =D7&E7&F7 | Y7: 5年交 | Z7: 67 | AA7: 70
Y8: 10年交 | Z8: 65 | AA8: 65
B9: 福盛世家添翼版终身寿险利益演示表 | S9: 一次交清，最低为 | U9: 50000
B10: 保单 年度 | C10: 年龄 | D10: 当期保费 （年初） | E10: 累计保费 （年初） | F10: 保险金额 （年末） | G10: 身故或全残保险金 | I10: 现金价值 | J10: 现价 增长率 | K10: 年化 收益 | L10: 现价 年增值 | M10: 现价 当年增速 | AB10: 一次交清 | AC10: 50000
G11: 一般身故 或全残 | H11: 特定公共 交通意外 | S11: =IF(D7=S5,VLOOKUP(F7,Y:Z,2,FALSE),VLOOKUP(F7,Y:AA,3,FALSE)) | AB11: 3年交 | AC11: 20000
B12: 1 | C12: =E7 | D12: =IF(B12="","",IF(B12<=IF($F$7="一次交清",1,IF($F$7="10年交",10,1*LEFT($F$7,1))),$H$7,0)) | E12: =IF(B12="","",SUM($D$12:D12)) | F12: =IFERROR(IF(B12="","",$J$7*(1.02^(B12-1))),"") | G12: =IF(B12="","",IF(C12<18,MAX(E12,I12),IF(B12<$O$7,E12*O12,MAX(F12,E12*O12,I12)))) | H12: =IF(B12="","",(IF(AND(C12>=18,C12<75),1,0)*$J$7)) | I12: =IFERROR(IF(B12="","",VLOOKUP(P12,现价!A:F,6,0)/1000)*$H$7,"") | J12: - | K12: =IF(B12="","",IF(I11<$H$7*$O$7,"-",IF($O$7=1,(I12-E12)/(E12*B12),IF($O$7=3,(I12-E12)/((B12-1)*E12),IF($O$7=5,(I12-E12)/((B12-2)*E12),(I12-E12)/((B12-4.5)*E12)))))) | L12: - | M12: - | O12: =IF(B12="","",VLOOKUP(C12,[1]给付系数!$A:$B,2)) | P12: =$D$7&$E$7&$F$7&B12 | AB12: 5年交 | AC12: 10000
B13: =IF(C12<104,B12+1,"") | C13: =IF(B13="","",$C$12+B13-1) | D13: =IF(B13="","",IF(B13<=IF($F$7="一次交清",1,IF($F$7="10年交",10,1*LEFT($F$7,1))),$H$7,0)) | E13: =IF(B13="","",SUM($D$12:D13)) | F13: =IFERROR(IF(B13="","",$J$7*(1.02^(B13-1))),"") | G13: =IF(B13="","",IF(C13<18,MAX(E13,I13),IF(B13<$O$7,E13*O13,MAX(F13,E13*O13,I13)))) | H13: =IF(B13="","",(IF(AND(C13>=18,C13<75),1,0)*$J$7)) | I13: =IFERROR(IF(B13="","",VLOOKUP(P13,现价!A:F,6,0)/1000)*$H$7,"") | J13: =IF(B13="","",IF(I12<=$H$7*$O$7,"-",(I13-I12)/I12)) | K13: =IF(B13="","",IF(I12<$H$7*$O$7,"-",IF($O$7=1,(I13-E13)/(E13*B13),IF($O$7=3,(I13-E13)/((B13-1)*E13),IF($O$7=5,(I13-E13)/((B13-2)*E13),(I13-E13)/((B13-4.5)*E13)))))) | L13: =IF(I12<$H$7*$O$7,"-",(IFERROR(I13-I12,""))) | M13: =IF(I12<$H$7*$O$7,"-",IFERROR((IF(B13>$E$9,1,0)*(I13-I12)/E13),"")) | O13: =IF(B13="","",VLOOKUP(C13,[1]给付系数!$A:$B,2)) | P13: =$D$7&$E$7&$F$7&B13 | AB13: 10年交 | AC13: 10000
B14: =IF(C13<104,B13+1,"") | C14: =IF(B14="","",$C$12+B14-1) | D14: =IF(B14="","",IF(B14<=IF($F$7="一次交清",1,IF($F$7="10年交",10,1*LEFT($F$7,1))),$H$7,0)) | E14: =IF(B14="","",SUM($D$12:D14)) | F14: =IFERROR(IF(B14="","",$J$7*(1.02^(B14-1))),"") | G14: =IF(B14="","",IF(C14<18,MAX(E14,I14),IF(B14<$O$7,E14*O14,MAX(F14,E14*O14,I14)))) | H14: =IF(B14="","",(IF(AND(C14>=18,C14<75),1,0)*$J$7)) | I14: =IFERROR(IF(B14="","",VLOOKUP(P14,现价!A:F,6,0)/1000)*$H$7,"") | J14: =IF(B14="","",IF(I13<=$H$7*$O$7,"-",(I14-I13)/I13)) | K14: =IF(B14="","",IF(I13<$H$7*$O$7,"-",IF($O$7=1,(I14-E14)/(E14*B14),IF($O$7=3,(I14-E14)/((B14-1)*E14),IF($O$7=5,(I14-E14)/((B14-2)*E14),(I14-E14)/((B14-4.5)*E14)))))) | L14: =IF(I13<$H$7*$O$7,"-",(IFERROR(I14-I13,""))) | M14: =IF(I13<$H$7*$O$7,"-",IFERROR((IF(B14>$E$9,1,0)*(I14-I13)/E14),"")) | O14: =IF(B14="","",VLOOKUP(C14,[1]给付系数!$A:$B,2)) | P14: =$D$7&$E$7&$F$7&B14 | AA14: =VLOOKUP(F7,AB:AC,2,0)
B15: =IF(C14<104,B14+1,"") | C15: =IF(B15="","",$C$12+B15-1) | D15: =IF(B15="","",IF(B15<=IF($F$7="一次交清",1,IF($F$7="10年交",10,1*LEFT($F$7,1))),$H$7,0)) | E15: =IF(B15="","",SUM($D$12:D15)) | F15: =IFERROR(IF(B15="","",$J$7*(1.02^(B15-1))),"") | G15: =IF(B15="","",IF(C15<18,MAX(E15,I15),IF(B15<$O$7,E15*O15,MAX(F15,E15*O15,I15)))) | H15: =IF(B15="","",(IF(AND(C15>=18,C15<75),1,0)*$J$7)) | I15: =IFERROR(IF(B15="","",VLOOKUP(P15,现价!A:F,6,0)/1000)*$H$7,"") | J15: =IF(B15="","",IF(I14<=$H$7*$O$7,"-",(I15-I14)/I14)) | K15: =IF(B15="","",IF(I14<$H$7*$O$7,"-",IF($O$7=1,(I15-E15)/(E15*B15),IF($O$7=3,(I15-E15)/((B15-1)*E15),IF($O$7=5,(I15-E15)/((B15-2)*E15),(I15-E15)/((B15-4.5)*E15)))))) | L15: =IF(I14<$H$7*$O$7,"-",(IFERROR(I15-I14,""))) | M15: =IF(I14<$H$7*$O$7,"-",IFERROR((IF(B15>$E$9,1,0)*(I15-I14)/E15),"")) | O15: =IF(B15="","",VLOOKUP(C15,[1]给付系数!$A:$B,2)) | P15: =$D$7&$E$7&$F$7&B15
B16: =IF(C15<104,B15+1,"") | C16: =IF(B16="","",$C$12+B16-1) | D16: =IF(B16="","",IF(B16<=IF($F$7="一次交清",1,IF($F$7="10年交",10,1*LEFT($F$7,1))),$H$7,0)) | E16: =IF(B16="","",SUM($D$12:D16)) | F16: =IFERROR(IF(B16="","",$J$7*(1.02^(B16-1))),"") | G16: =IF(B16="","",IF(C16<18,MAX(E16,I16),IF(B16<$O$7,E16*O16,MAX(F16,E16*O16,I16)))) | H16: =IF(B16="","",(IF(AND(C16>=18,C16<75),1,0)*$J$7)) | I16: =IFERROR(IF(B16="","",VLOOKUP(P16,现价!A:F,6,0)/1000)*$H$7,"") | J16: =IF(B16="","",IF(I15<=$H$7*$O$7,"-",(I16-I15)/I15)) | K16: =IF(B16="","",IF(I15<$H$7*$O$7,"-",IF($O$7=1,(I16-E16)/(E16*B16),IF($O$7=3,(I16-E16)/((B16-1)*E16),IF($O$7=5,(I16-E16)/((B16-2)*E16),(I16-E16)/((B16-4.5)*E16)))))) | L16: =IF(I15<$H$7*$O$7,"-",(IFERROR(I16-I15,""))) | M16: =IF(I15<$H$7*$O$7,"-",IFERROR((IF(B16>$E$9,1,0)*(I16-I15)/E16),"")) | O16: =IF(B16="","",VLOOKUP(C16,[1]给付系数!$A:$B,2)) | P16: =$D$7&$E$7&$F$7&B16
B17: =IF(C16<104,B16+1,"") | C17: =IF(B17="","",$C$12+B17-1) | D17: =IF(B17="","",IF(B17<=IF($F$7="一次交清",1,IF($F$7="10年交",10,1*LEFT($F$7,1))),$H$7,0)) | E17: =IF(B17="","",SUM($D$12:D17)) | F17: =IFERROR(IF(B17="","",$J$7*(1.02^(B17-1))),"") | G17: =IF(B17="","",IF(C17<18,MAX(E17,I17),IF(B17<$O$7,E17*O17,MAX(F17,E17*O17,I17)))) | H17: =IF(B17="","",(IF(AND(C17>=18,C17<75),1,0)*$J$7)) | I17: =IFERROR(IF(B17="","",VLOOKUP(P17,现价!A:F,6,0)/1000)*$H$7,"") | J17: =IF(B17="","",IF(I16<=$H$7*$O$7,"-",(I17-I16)/I16)) | K17: =IF(B17="","",IF(I16<$H$7*$O$7,"-",IF($O$7=1,(I17-E17)/(E17*B17),IF($O$7=3,(I17-E17)/((B17-1)*E17),IF($O$7=5,(I17-E17)/((B17-2)*E17),(I17-E17)/((B17-4.5)*E17)))))) | L17: =IF(I16<$H$7*$O$7,"-",(IFERROR(I17-I16,""))) | M17: =IF(I16<$H$7*$O$7,"-",IFERROR((IF(B17>$E$9,1,0)*(I17-I16)/E17),"")) | O17: =IF(B17="","",VLOOKUP(C17,[1]给付系数!$A:$B,2)) | P17: =$D$7&$E$7&$F$7&B17
B18: =IF(C17<104,B17+1,"") | C18: =IF(B18="","",$C$12+B18-1) | D18: =IF(B18="","",IF(B18<=IF($F$7="一次交清",1,IF($F$7="10年交",10,1*LEFT($F$7,1))),$H$7,0)) | E18: =IF(B18="","",SUM($D$12:D18)) | F18: =IFERROR(IF(B18="","",$J$7*(1.02^(B18-1))),"") | G18: =IF(B18="","",IF(C18<18,MAX(E18,I18),IF(B18<$O$7,E18*O18,MAX(F18,E18*O18,I18)))) | H18: =IF(B18="","",(IF(AND(C18>=18,C18<75),1,0)*$J$7)) | I18: =IFERROR(IF(B18="","",VLOOKUP(P18,现价!A:F,6,0)/1000)*$H$7,"") | J18: =IF(B18="","",IF(I17<=$H$7*$O$7,"-",(I18-I17)/I17)) | K18: =IF(B18="","",IF(I17<$H$7*$O$7,"-",IF($O$7=1,(I18-E18)/(E18*B18),IF($O$7=3,(I18-E18)/((B18-1)*E18),IF($O$7=5,(I18-E18)/((B18-2)*E18),(I18-E18)/((B18-4.5)*E18)))))) | L18: =IF(I17<$H$7*$O$7,"-",(IFERROR(I18-I17,""))) | M18: =IF(I17<$H$7*$O$7,"-",IFERROR((IF(B18>$E$9,1,0)*(I18-I17)/E18),"")) | O18: =IF(B18="","",VLOOKUP(C18,[1]给付系数!$A:$B,2)) | P18: =$D$7&$E$7&$F$7&B18
B19: =IF(C18<104,B18+1,"") | C19: =IF(B19="","",$C$12+B19-1) | D19: =IF(B19="","",IF(B19<=IF($F$7="一次交清",1,IF($F$7="10年交",10,1*LEFT($F$7,1))),$H$7,0)) | E19: =IF(B19="","",SUM($D$12:D19)) | F19: =IFERROR(IF(B19="","",$J$7*(1.02^(B19-1))),"") | G19: =IF(B19="","",IF(C19<18,MAX(E19,I19),IF(B19<$O$7,E19*O19,MAX(F19,E19*O19,I19)))) | H19: =IF(B19="","",(IF(AND(C19>=18,C19<75),1,0)*$J$7)) | I19: =IFERROR(IF(B19="","",VLOOKUP(P19,现价!A:F,6,0)/1000)*$H$7,"") | J19: =IF(B19="","",IF(I18<=$H$7*$O$7,"-",(I19-I18)/I18)) | K19: =IF(B19="","",IF(I18<$H$7*$O$7,"-",IF($O$7=1,(I19-E19)/(E19*B19),IF($O$7=3,(I19-E19)/((B19-1)*E19),IF($O$7=5,(I19-E19)/((B19-2)*E19),(I19-E19)/((B19-4.5)*E19)))))) | L19: =IF(I18<$H$7*$O$7,"-",(IFERROR(I19-I18,""))) | M19: =IF(I18<$H$7*$O$7,"-",IFERROR((IF(B19>$E$9,1,0)*(I19-I18)/E19),"")) | O19: =IF(B19="","",VLOOKUP(C19,[1]给付系数!$A:$B,2)) | P19: =$D$7&$E$7&$F$7&B19
B20: =IF(C19<104,B19+1,"") | C20: =IF(B20="","",$C$12+B20-1) | D20: =IF(B20="","",IF(B20<=IF($F$7="一次交清",1,IF($F$7="10年交",10,1*LEFT($F$7,1))),$H$7,0)) | E20: =IF(B20="","",SUM($D$12:D20)) | F20: =IFERROR(IF(B20="","",$J$7*(1.02^(B20-1))),"") | G20: =IF(B20="","",IF(C20<18,MAX(E20,I20),IF(B20<$O$7,E20*O20,MAX(F20,E20*O20,I20)))) | H20: =IF(B20="","",(IF(AND(C20>=18,C20<75),1,0)*$J$7)) | I20: =IFERROR(IF(B20="","",VLOOKUP(P20,现价!A:F,6,0)/1000)*$H$7,"") | J20: =IF(B20="","",IF(I19<=$H$7*$O$7,"-",(I20-I19)/I19)) | K20: =IF(B20="","",IF(I19<$H$7*$O$7,"-",IF($O$7=1,(I20-E20)/(E20*B20),IF($O$7=3,(I20-E20)/((B20-1)*E20),IF($O$7=5,(I20-E20)/((B20-2)*E20),(I20-E20)/((B20-4.5)*E20)))))) | L20: =IF(I19<$H$7*$O$7,"-",(IFERROR(I20-I19,""))) | M20: =IF(I19<$H$7*$O$7,"-",IFERROR((IF(B20>$E$9,1,0)*(I20-I19)/E20),"")) | O20: =IF(B20="","",VLOOKUP(C20,[1]给付系数!$A:$B,2)) | P20: =$D$7&$E$7&$F$7&B20
B21: =IF(C20<104,B20+1,"") | C21: =IF(B21="","",$C$12+B21-1) | D21: =IF(B21="","",IF(B21<=IF($F$7="一次交清",1,IF($F$7="10年交",10,1*LEFT($F$7,1))),$H$7,0)) | E21: =IF(B21="","",SUM($D$12:D21)) | F21: =IFERROR(IF(B21="","",$J$7*(1.02^(B21-1))),"") | G21: =IF(B21="","",IF(C21<18,MAX(E21,I21),IF(B21<$O$7,E21*O21,MAX(F21,E21*O21,I21)))) | H21: =IF(B21="","",(IF(AND(C21>=18,C21<75),1,0)*$J$7)) | I21: =IFERROR(IF(B21="","",VLOOKUP(P21,现价!A:F,6,0)/1000)*$H$7,"") | J21: =IF(B21="","",IF(I20<=$H$7*$O$7,"-",(I21-I20)/I20)) | K21: =IF(B21="","",IF(I20<$H$7*$O$7,"-",IF($O$7=1,(I21-E21)/(E21*B21),IF($O$7=3,(I21-E21)/((B21-1)*E21),IF($O$7=5,(I21-E21)/((B21-2)*E21),(I21-E21)/((B21-4.5)*E21)))))) | L21: =IF(I20<$H$7*$O$7,"-",(IFERROR(I21-I20,""))) | M21: =IF(I20<$H$7*$O$7,"-",IFERROR((IF(B21>$E$9,1,0)*(I21-I20)/E21),"")) | O21: =IF(B21="","",VLOOKUP(C21,[1]给付系数!$A:$B,2)) | P21: =$D$7&$E$7&$F$7&B21
B22: =IF(C21<104,B21+1,"") | C22: =IF(B22="","",$C$12+B22-1) | D22: =IF(B22="","",IF(B22<=IF($F$7="一次交清",1,IF($F$7="10年交",10,1*LEFT($F$7,1))),$H$7,0)) | E22: =IF(B22="","",SUM($D$12:D22)) | F22: =IFERROR(IF(B22="","",$J$7*(1.02^(B22-1))),"") | G22: =IF(B22="","",IF(C22<18,MAX(E22,I22),IF(B22<$O$7,E22*O22,MAX(F22,E22*O22,I22)))) | H22: =IF(B22="","",(IF(AND(C22>=18,C22<75),1,0)*$J$7)) | I22: =IFERROR(IF(B22="","",VLOOKUP(P22,现价!A:F,6,0)/1000)*$H$7,"") | J22: =IF(B22="","",IF(I21<=$H$7*$O$7,"-",(I22-I21)/I21)) | K22: =IF(B22="","",IF(I21<$H$7*$O$7,"-",IF($O$7=1,(I22-E22)/(E22*B22),IF($O$7=3,(I22-E22)/((B22-1)*E22),IF($O$7=5,(I22-E22)/((B22-2)*E22),(I22-E22)/((B22-4.5)*E22)))))) | L22: =IF(I21<$H$7*$O$7,"-",(IFERROR(I22-I21,""))) | M22: =IF(I21<$H$7*$O$7,"-",IFERROR((IF(B22>$E$9,1,0)*(I22-I21)/E22),"")) | O22: =IF(B22="","",VLOOKUP(C22,[1]给付系数!$A:$B,2)) | P22: =$D$7&$E$7&$F$7&B22
B23: =IF(C22<104,B22+1,"") | C23: =IF(B23="","",$C$12+B23-1) | D23: =IF(B23="","",IF(B23<=IF($F$7="一次交清",1,IF($F$7="10年交",10,1*LEFT($F$7,1))),$H$7,0)) | E23: =IF(B23="","",SUM($D$12:D23)) | F23: =IFERROR(IF(B23="","",$J$7*(1.02^(B23-1))),"") | G23: =IF(B23="","",IF(C23<18,MAX(E23,I23),IF(B23<$O$7,E23*O23,MAX(F23,E23*O23,I23)))) | H23: =IF(B23="","",(IF(AND(C23>=18,C23<75),1,0)*$J$7)) | I23: =IFERROR(IF(B23="","",VLOOKUP(P23,现价!A:F,6,0)/1000)*$H$7,"") | J23: =IF(B23="","",IF(I22<=$H$7*$O$7,"-",(I23-I22)/I22)) | K23: =IF(B23="","",IF(I22<$H$7*$O$7,"-",IF($O$7=1,(I23-E23)/(E23*B23),IF($O$7=3,(I23-E23)/((B23-1)*E23),IF($O$7=5,(I23-E23)/((B23-2)*E23),(I23-E23)/((B23-4.5)*E23)))))) | L23: =IF(I22<$H$7*$O$7,"-",(IFERROR(I23-I22,""))) | M23: =IF(I22<$H$7*$O$7,"-",IFERROR((IF(B23>$E$9,1,0)*(I23-I22)/E23),"")) | O23: =IF(B23="","",VLOOKUP(C23,[1]给付系数!$A:$B,2)) | P23: =$D$7&$E$7&$F$7&B23
B24: =IF(C23<104,B23+1,"") | C24: =IF(B24="","",$C$12+B24-1) | D24: =IF(B24="","",IF(B24<=IF($F$7="一次交清",1,IF($F$7="10年交",10,1*LEFT($F$7,1))),$H$7,0)) | E24: =IF(B24="","",SUM($D$12:D24)) | F24: =IFERROR(IF(B24="","",$J$7*(1.02^(B24-1))),"") | G24: =IF(B24="","",IF(C24<18,MAX(E24,I24),IF(B24<$O$7,E24*O24,MAX(F24,E24*O24,I24)))) | H24: =IF(B24="","",(IF(AND(C24>=18,C24<75),1,0)*$J$7)) | I24: =IFERROR(IF(B24="","",VLOOKUP(P24,现价!A:F,6,0)/1000)*$H$7,"") | J24: =IF(B24="","",IF(I23<=$H$7*$O$7,"-",(I24-I23)/I23)) | K24: =IF(B24="","",IF(I23<$H$7*$O$7,"-",IF($O$7=1,(I24-E24)/(E24*B24),IF($O$7=3,(I24-E24)/((B24-1)*E24),IF($O$7=5,(I24-E24)/((B24-2)*E24),(I24-E24)/((B24-4.5)*E24)))))) | L24: =IF(I23<$H$7*$O$7,"-",(IFERROR(I24-I23,""))) | M24: =IF(I23<$H$7*$O$7,"-",IFERROR((IF(B24>$E$9,1,0)*(I24-I23)/E24),"")) | O24: =IF(B24="","",VLOOKUP(C24,[1]给付系数!$A:$B,2)) | P24: =$D$7&$E$7&$F$7&B24
B25: =IF(C24<104,B24+1,"") | C25: =IF(B25="","",$C$12+B25-1) | D25: =IF(B25="","",IF(B25<=IF($F$7="一次交清",1,IF($F$7="10年交",10,1*LEFT($F$7,1))),$H$7,0)) | E25: =IF(B25="","",SUM($D$12:D25)) | F25: =IFERROR(IF(B25="","",$J$7*(1.02^(B25-1))),"") | G25: =IF(B25="","",IF(C25<18,MAX(E25,I25),IF(B25<$O$7,E25*O25,MAX(F25,E25*O25,I25)))) | H25: =IF(B25="","",(IF(AND(C25>=18,C25<75),1,0)*$J$7)) | I25: =IFERROR(IF(B25="","",VLOOKUP(P25,现价!A:F,6,0)/1000)*$H$7,"") | J25: =IF(B25="","",IF(I24<=$H$7*$O$7,"-",(I25-I24)/I24)) | K25: =IF(B25="","",IF(I24<$H$7*$O$7,"-",IF($O$7=1,(I25-E25)/(E25*B25),IF($O$7=3,(I25-E25)/((B25-1)*E25),IF($O$7=5,(I25-E25)/((B25-2)*E25),(I25-E25)/((B25-4.5)*E25)))))) | L25: =IF(I24<$H$7*$O$7,"-",(IFERROR(I25-I24,""))) | M25: =IF(I24<$H$7*$O$7,"-",IFERROR((IF(B25>$E$9,1,0)*(I25-I24)/E25),"")) | O25: =IF(B25="","",VLOOKUP(C25,[1]给付系数!$A:$B,2)) | P25: =$D$7&$E$7&$F$7&B25
B26: =IF(C25<104,B25+1,"") | C26: =IF(B26="","",$C$12+B26-1) | D26: =IF(B26="","",IF(B26<=IF($F$7="一次交清",1,IF($F$7="10年交",10,1*LEFT($F$7,1))),$H$7,0)) | E26: =IF(B26="","",SUM($D$12:D26)) | F26: =IFERROR(IF(B26="","",$J$7*(1.02^(B26-1))),"") | G26: =IF(B26="","",IF(C26<18,MAX(E26,I26),IF(B26<$O$7,E26*O26,MAX(F26,E26*O26,I26)))) | H26: =IF(B26="","",(IF(AND(C26>=18,C26<75),1,0)*$J$7)) | I26: =IFERROR(IF(B26="","",VLOOKUP(P26,现价!A:F,6,0)/1000)*$H$7,"") | J26: =IF(B26="","",IF(I25<=$H$7*$O$7,"-",(I26-I25)/I25)) | K26: =IF(B26="","",IF(I25<$H$7*$O$7,"-",IF($O$7=1,(I26-E26)/(E26*B26),IF($O$7=3,(I26-E26)/((B26-1)*E26),IF($O$7=5,(I26-E26)/((B26-2)*E26),(I26-E26)/((B26-4.5)*E26)))))) | L26: =IF(I25<$H$7*$O$7,"-",(IFERROR(I26-I25,""))) | M26: =IF(I25<$H$7*$O$7,"-",IFERROR((IF(B26>$E$9,1,0)*(I26-I25)/E26),"")) | O26: =IF(B26="","",VLOOKUP(C26,[1]给付系数!$A:$B,2)) | P26: =$D$7&$E$7&$F$7&B26
... B116: =IF(C115<104,B115+1,"") | C116: =IF(B116="","",$C$12+B116-1) | D116: =IF(B116="","",IF(B116<=IF($F$7="一次交清",1,IF($F$7="10年交",10,1*LEFT($F$7,1))),$H$7,0)) | E116: =IF(B116="","",SUM($D$12:D116)) | F116: =IFERROR(IF(B116="","",$J$7*(1.02^(B116-1))),"") | G116: =IF(B116="","",IF(C116<18,MAX(E116,I116),IF(B116<$O$7,E116*O116,MAX(F116,E116*O116,I116)))) | H116: =IF(B116="","",(IF(AND(C116>=18,C116<75),1,0)*$J$7)) | I116: =IFERROR(IF(B116="","",VLOOKUP(P116,现价!A:F,6,0)/1000)*$H$7,"") | J116: =IF(B116="","",IF(I115<=$H$7*$O$7,"-",(I116-I115)/I115)) | K116: =IF(B116="","",IF(I115<$H$7*$O$7,"-",IF($O$7=1,(I116-E116)/(E116*B116),IF($O$7=3,(I116-E116)/((B116-1)*E116),IF($O$7=5,(I116-E116)/((B116-2)*E116),(I116-E116)/((B116-4.5)*E116)))))) | L116: =IF(I115<$H$7*$O$7,"-",(IFERROR(I116-I115,""))) | M116: =IF(I115<$H$7*$O$7,"-",IFERROR((IF(B116>$E$9,1,0)*(I116-I115)/E116),"")) | O116: =IF(B116="","",VLOOKUP(C116,[1]给付系数!$A:$B,2)) | P116: =$D$7&$E$7&$F$7&B116
B117: 注：1.上述演示数据经过取整处理。2.合同生效180日（含）内的保险责任请参见产品条款。3.犹豫期后，本合同退保金为“现金价值”。

Sheet 保额
A1: 性别 | B1: 年龄 | C1: 交费期间 | E1: 保额
A2: 男 | B2: 0 | C2: 一次交清 | D2: =A2&B2&C2 | E2: 937
A3: 男 | B3: 1 | C3: 一次交清 | D3: =A3&B3&C3 | E3: 937
A4: 男 | B4: 2 | C4: 一次交清 | D4: =A4&B4&C4 | E4: 937
A5: 男 | B5: 3 | C5: 一次交清 | D5: =A5&B5&C5 | E5: 937
A6: 男 | B6: 4 | C6: 一次交清 | D6: =A6&B6&C6 | E6: 936
A7: 男 | B7: 5 | C7: 一次交清 | D7: =A7&B7&C7 | E7: 936
A8: 男 | B8: 6 | C8: 一次交清 | D8: =A8&B8&C8 | E8: 936
A9: 男 | B9: 7 | C9: 一次交清 | D9: =A9&B9&C9 | E9: 936
A10: 男 | B10: 8 | C10: 一次交清 | D10: =A10&B10&C10 | E10: 936
A11: 男 | B11: 9 | C11: 一次交清 | D11: =A11&B11&C11 | E11: 935
A12: 男 | B12: 10 | C12: 一次交清 | D12: =A12&B12&C12 | E12: 935
A13: 男 | B13: 11 | C13: 一次交清 | D13: =A13&B13&C13 | E13: 935
... A70: 男 | B70: 68 | C70: 一次交清 | D70: =A70&B70&C70 | E70: 790
A73: 性别 | B73: 年龄 | C73: 交费期间 | D73: =A73&B73&C73 | E73: 保额
A74: 男 | B74: 0 | C74: 3年交 | D74: =A74&B74&C74 | E74: 2803
A75: 男 | B75: 1 | C75: 3年交 | D75: =A75&B75&C75 | E75: 2803
A76: 男 | B76: 2 | C76: 3年交 | D76: =A76&B76&C76 | E76: 2803
A77: 男 | B77: 3 | C77: 3年交 | D77: =A77&B77&C77 | E77: 2802
A78: 男 | B78: 4 | C78: 3年交 | D78: =A78&B78&C78 | E78: 2802
A79: 男 | B79: 5 | C79: 3年交 | D79: =A79&B79&C79 | E79: 2801
A80: 男 | B80: 6 | C80: 3年交 | D80: =A80&B80&C80 | E80: 2800
A81: 男 | B81: 7 | C81: 3年交 | D81: =A81&B81&C81 | E81: 2800
A82: 男 | B82: 8 | C82: 3年交 | D82: =A82&B82&C82 | E82: 2799
A83: 男 | B83: 9 | C83: 3年交 | D83: =A83&B83&C83 | E83: 2798
A84: 男 | B84: 10 | C84: 3年交 | D84: =A84&B84&C84 | E84: 2797
A85: 男 | B85: 11 | C85: 3年交 | D85: =A85&B85&C85 | E85: 2796
... A142: 男 | B142: 68 | C142: 3年交 | D142: =A142&B142&C142 | E142: 2397
A144: 性别 | B144: 年龄 | C144: 交费期间 | D144: =A144&B144&C144 | E144: 保额
A145: 男 | B145: 0 | C145: 5年交 | D145: =A145&B145&C145 | E145: 4553
A146: 男 | B146: 1 | C146: 5年交 | D146: =A146&B146&C146 | E146: 4552
A147: 男 | B147: 2 | C147: 5年交 | D147: =A147&B147&C147 | E147: 4551
A148: 男 | B148: 3 | C148: 5年交 | D148: =A148&B148&C148 | E148: 4550
A149: 男 | B149: 4 | C149: 5年交 | D149: =A149&B149&C149 | E149: 4549
A150: 男 | B150: 5 | C150: 5年交 | D150: =A150&B150&C150 | E150: 4548
A151: 男 | B151: 6 | C151: 5年交 | D151: =A151&B151&C151 | E151: 4547
A152: 男 | B152: 7 | C152: 5年交 | D152: =A152&B152&C152 | E152: 4546
A153: 男 | B153: 8 | C153: 5年交 | D153: =A153&B153&C153 | E153: 4544
A154: 男 | B154: 9 | C154: 5年交 | D154: =A154&B154&C154 | E154: 4542
A155: 男 | B155: 10 | C155: 5年交 | D155: =A155&B155&C155 | E155: 4541
...

Sheet 现价
B1: 新华人寿保险股份有限公司
B2: 福盛世家添翼版终身寿险现金价值表
B3: 一次交清或年交保险费：1000元 单位：元
A5: 类别 | B5: 性别 | C5: 投保年龄（周岁） | D5: 交费方式 | E5: 保单年度末 | F5: 现金价值
A6: =B6&C6&D6&E6 | B6: 男 | C6: 0 | D6: 一次交清 | E6: 1 | F6: 224
A7: =B7&C7&D7&E7 | B7: 男 | C7: 0 | D7: 一次交清 | E7: 2 | F7: 474
A8: =B8&C8&D8&E8 | B8: 男 | C8: 0 | D8: 一次交清 | E8: 3 | F8: 731
A9: =B9&C9&D9&E9 | B9: 男 | C9: 0 | D9: 一次交清 | E9: 4 | F9: 996
A10: =B10&C10&D10&E10 | B10: 男 | C10: 0 | D10: 一次交清 | E10: 5 | F10: 1016
A11: =B11&C11&D11&E11 | B11: 男 | C11: 0 | D11: 一次交清 | E11: 6 | F11: 1036
A12: =B12&C12&D12&E12 | B12: 男 | C12: 0 | D12: 一次交清 | E12: 7 | F12: 1057
A13: =B13&C13&D13&E13 | B13: 男 | C13: 0 | D13: 一次交清 | E13: 8 | F13: 1078
A14: =B14&C14&D14&E14 | B14: 男 | C14: 0 | D14: 一次交清 | E14: 9 | F14: 1099
A15: =B15&C15&D15&E15 | B15: 男 | C15: 0 | D15: 一次交清 | E15: 10 | F15: 1121
A16: =B16&C16&D16&E16 | B16: 男 | C16: 0 | D16: 一次交清 | E16: 11 | F16: 1144
A17: =B17&C17&D17&E17 | B17: 男 | C17: 0 | D17: 一次交清 | E17: 12 | F17: 1167
... A39279: =B39279&C39279&D39279&E39279 | B39279: 女 | C39279: 65 | D39279: 10年交 | E39279: 40 | F39279: 17718
